<?xml version="1.0" ?>
<!-- =================================================================================== -->
<!-- |    This document was autogenerated by xacro from src/fbot_description/boris_description/urdf/boris_full.xacro | -->
<!-- |    EDITING THIS FILE BY HAND IS NOT RECOMMENDED                                 | -->
<!-- =================================================================================== -->
<robot name="boris">
  <link name="base_footprint">
  </link>
  <link name="base_link">
    <inertial>
      <mass value="1"/>
      <inertia ixx="0.009360416666666668" ixy="0.0" ixz="0.0" iyy="0.030185416666666666" iyz="0.0" izz="0.020841666666666665"/>
    </inertial>
    <visual>
      <material name="lightgray"/>
      <geometry>
        <box size="0.5 0.335 0.235"/>
      </geometry>
    </visual>
    <collision>
      <geometry>
        <box size="0.5 0.335 0.235"/>
      </geometry>
    </collision>
  </link>
  <joint name="base_link_joint" type="fixed">
    <origin rpy="0 0 0" xyz="0 0 0.1875"/>
    <parent link="base_footprint"/>
    <child link="base_link"/>
  </joint>
  <link name="left_wheel">
    <visual>
      <material name="darkgray"/>
      <origin rpy="1.5707963267948966 0 0" xyz="0 0 0"/>
      <geometry>
        <cylinder length="0.06" radius="0.0775"/>
      </geometry>
    </visual>
    <collision>
      <origin rpy="1.5707963267948966 0 0" xyz="0 0 0"/>
      <geometry>
        <cylinder length="0.05" radius="0.0775"/>
      </geometry>
    </collision>
    <inertial>
      <mass value="10"/>
      <inertia ixx="0.017098958333333334" ixy="0" ixz="0" iyy="0.017098958333333334" iyz="0" izz="0.03003125"/>
    </inertial>
  </link>
  <joint name="left_wheel_joint" type="continuous">
    <axis rpy="0 0 0" xyz="0 1 0"/>
    <parent link="base_link"/>
    <child link="left_wheel"/>
    <origin rpy="0 0 0" xyz="0.0 0.21750000000000003 -0.11"/>
  </joint>
  <link name="right_wheel">
    <visual>
      <material name="darkgray"/>
      <origin rpy="1.5707963267948966 0 0" xyz="0 0 0"/>
      <geometry>
        <cylinder length="0.06" radius="0.0775"/>
      </geometry>
    </visual>
    <collision>
      <origin rpy="1.5707963267948966 0 0" xyz="0 0 0"/>
      <geometry>
        <cylinder length="0.05" radius="0.0775"/>
      </geometry>
    </collision>
    <inertial>
      <mass value="10"/>
      <inertia ixx="0.017098958333333334" ixy="0" ixz="0" iyy="0.017098958333333334" iyz="0" izz="0.03003125"/>
    </inertial>
  </link>
  <joint name="right_wheel_joint" type="continuous">
    <axis rpy="0 0 0" xyz="0 1 0"/>
    <parent link="base_link"/>
    <child link="right_wheel"/>
    <origin rpy="0 0 0" xyz="0.0 -0.21750000000000003 -0.11"/>
  </joint>
  <link name="caster_wheel">
    <visual>
      <material name="darkgray"/>
      <origin rpy="0 0 0" xyz="0 0 0"/>
      <geometry>
        <sphere radius="0.02"/>
      </geometry>
    </visual>
    <collision>
      <origin rpy="0 0 0" xyz="0 0 0"/>
      <geometry>
        <sphere radius="0.02"/>
      </geometry>
    </collision>
    <inertial>
      <mass value="5"/>
      <inertia ixx="0.0008" ixy="0.0" ixz="0.0" iyy="0.0008" iyz="0.0" izz="0.0008"/>
    </inertial>
  </link>
  <joint name="caster_wheel_joint" type="continuous">
    <axis rpy="0 0 0" xyz="0 1 0"/>
    <parent link="base_link"/>
    <child link="caster_wheel"/>
    <origin rpy="0 0 0" xyz="0.25 0 -0.16749999999999998"/>
  </joint>
  <material name="blue">
    <color rgba="0 0 0.8 1"/>
  </material>
  <material name="black">
    <color rgba="0 0 0 1"/>
  </material>
  <material name="darkgray">
    <color rgba="0.2 0.2 0.2 1"/>
  </material>
  <material name="lightgray">
    <color rgba="0.8 0.8 0.8 1"/>
  </material>
  <material name="white">
    <color rgba="1 1 1 1"/>
  </material>
  <material name="red">
    <color rgba="0.8 0.0 0.0 1.0"/>
  </material>
  <gazebo>
    <plugin filename="libgazebo_ros_diff_drive.so" name="diff_drive">
      <ros>
        <namespace>/</namespace>
      </ros>
      <left_joint>left_wheel_joint</left_joint>
      <right_joint>right_wheel_joint</right_joint>
      <wheel_separation>0.41</wheel_separation>
      <wheel_diameter>0.0775</wheel_diameter>
      <update_rate>500</update_rate>
      <max_wheel_torque>200</max_wheel_torque>
      <max_wheel_acceleration>10.0</max_wheel_acceleration>
      <odometry_frame>odom</odometry_frame>
      <robot_base_frame>base_footprint</robot_base_frame>
      <publish_odom>true</publish_odom>
      <publish_odom_tf>true</publish_odom_tf>
      <publish_wheel_tf>true</publish_wheel_tf>
    </plugin>
  </gazebo>
  <gazebo>
    <link name="base_link">
      <sensor name="imu" type="imu">
        <always_on>true</always_on>
        <update_rate>30</update_rate>
        <plugin filename="libgazebo_ros_imu_sensor.so" name="imu_plugin">
          <ros>
            <namespace>/bno055</namespace>
            <remapping>~/out:=imu</remapping>
          </ros>
        </plugin>
      </sensor>
    </link>
  </gazebo>
  <gazebo reference="base_link">
    <material>Gazebo/DarkGray</material>
  </gazebo>
  <gazebo reference="left_wheel">
    <material>Gazebo/Black</material>
  </gazebo>
  <gazebo reference="right_wheel">
    <material>Gazebo/Black</material>
  </gazebo>
  <link name="head_link">
    <inertial>
      <origin rpy="0 0 0" xyz="0 0 0"/>
      <mass value="0.001"/>
      <inertia ixx="0.001" ixy="0" ixz="0" iyy="0.001" iyz="0" izz="0.001"/>
    </inertial>
    <visual name="head">
      <origin rpy="1.5708 0 0" xyz="-0.02248 -0.11374 -0.02141"/>
      <geometry>
        <mesh filename="package://boris_head_description/meshes/dae/Cube.001.dae" scale="0.001 0.001 0.001"/>
      </geometry>
      <material name="Gray_001"/>
    </visual>
  </link>
  <link name="jaw_link">
    <inertial>
      <origin rpy="0 0 0" xyz="0 0 0"/>
      <mass value="0.001"/>
      <inertia ixx="0.001" ixy="0" ixz="0" iyy="0.001" iyz="0" izz="0.001"/>
    </inertial>
    <visual name="jaw">
      <origin rpy="1.5708 0 0" xyz="0.05463 0.06043 -0.08008"/>
      <geometry>
        <mesh filename="package://boris_head_description/meshes/dae/Plane.012.dae" scale="0.001 0.001 0.001"/>
      </geometry>
      <material name="Face_000"/>
    </visual>
  </link>
  <link name="left_eye_horizontal_link">
    <inertial>
      <origin rpy="0 0 0" xyz="0 0 0"/>
      <mass value="0.001"/>
      <inertia ixx="0.001" ixy="0" ixz="0" iyy="0.001" iyz="0" izz="0.001"/>
    </inertial>
  </link>
  <link name="left_eye_vertical_link">
    <inertial>
      <origin rpy="0 0 0" xyz="0 0 0"/>
      <mass value="0.001"/>
      <inertia ixx="0.001" ixy="0" ixz="0" iyy="0.001" iyz="0" izz="0.001"/>
    </inertial>
    <visual name="left_eye">
      <origin rpy="-1.5708 0 0" xyz="0 0 0"/>
      <geometry>
        <mesh filename="package://boris_head_description/meshes/dae/Cube.002.dae" scale="0.001 0.001 0.001"/>
      </geometry>
      <material name="WHITE_003"/>
    </visual>
  </link>
  <link name="left_inferior_eyelid_link">
    <inertial>
      <origin rpy="0 0 0" xyz="0 0 0"/>
      <mass value="0.001"/>
      <inertia ixx="0.001" ixy="0" ixz="0" iyy="0.001" iyz="0" izz="0.001"/>
    </inertial>
    <visual name="left_inferior_eyelid">
      <origin rpy="-1.56706 -0.06102 -0.06125" xyz="0.00498 -0.01247 -0.02356"/>
      <geometry>
        <mesh filename="package://boris_head_description/meshes/dae/Plane.015.dae" scale="0.001 0.001 0.001"/>
      </geometry>
      <material name="Gray_001"/>
    </visual>
  </link>
  <link name="left_rotacional_eyebrow_link">
    <inertial>
      <origin rpy="0 0 0" xyz="0 0 0"/>
      <mass value="0.001"/>
      <inertia ixx="0.001" ixy="0" ixz="0" iyy="0.001" iyz="0" izz="0.001"/>
    </inertial>
    <visual name="left_eyebrow">
      <origin rpy="0 0 0" xyz="0 0 0"/>
      <geometry>
        <mesh filename="package://boris_head_description/meshes/dae/Cylinder.004.dae" scale="0.001 0.001 0.001"/>
      </geometry>
      <material name="BLACK_006"/>
    </visual>
  </link>
  <link name="left_superior_eyelid_link">
    <inertial>
      <origin rpy="0 0 0" xyz="0 0 0"/>
      <mass value="0.001"/>
      <inertia ixx="0.001" ixy="0" ixz="0" iyy="0.001" iyz="0" izz="0.001"/>
    </inertial>
    <visual name="left_superior_eyelid">
      <origin rpy="1.5708 -0.06113 0" xyz="0.00551 -0.01216 -0.01543"/>
      <geometry>
        <mesh filename="package://boris_head_description/meshes/dae/Plane.001.dae" scale="0.001 0.001 0.001"/>
      </geometry>
      <material name="Gray_001"/>
    </visual>
  </link>
  <link name="left_vertical_eyebrow_link">
    <inertial>
      <origin rpy="0 0 0" xyz="0 0 0"/>
      <mass value="0.001"/>
      <inertia ixx="0.001" ixy="0" ixz="0" iyy="0.001" iyz="0" izz="0.001"/>
    </inertial>
  </link>
  <link name="neck_link">
    <inertial>
      <origin rpy="0 0 0" xyz="0 0 0"/>
      <mass value="0.001"/>
      <inertia ixx="0.001" ixy="0" ixz="0" iyy="0.001" iyz="0" izz="0.001"/>
    </inertial>
    <visual name="neck">
      <origin rpy="0 0 0" xyz="0 0 0"/>
      <geometry>
        <mesh filename="package://boris_head_description/meshes/dae/Cube.055.dae" scale="0.01 0.01 0.01"/>
      </geometry>
    </visual>
  </link>
  <link name="right_rotacional_eyebrow_link">
    <inertial>
      <origin rpy="0 0 0" xyz="0 0 0"/>
      <mass value="0.001"/>
      <inertia ixx="0.001" ixy="0" ixz="0" iyy="0.001" iyz="0" izz="0.001"/>
    </inertial>
    <visual name="right_eyebrow">
      <origin rpy="0 0 0" xyz="0 0 0"/>
      <geometry>
        <mesh filename="package://boris_head_description/meshes/dae/Cylinder.005.dae" scale="0.001 0.001 0.001"/>
      </geometry>
      <material name="BLACK_007"/>
    </visual>
  </link>
  <link name="right_vertical_eyebrow_link">
    <inertial>
      <origin rpy="0 0 0" xyz="0 0 0"/>
      <mass value="0.001"/>
      <inertia ixx="0.001" ixy="0" ixz="0" iyy="0.001" iyz="0" izz="0.001"/>
    </inertial>
  </link>
  <link name="right_eye_horizontal_link">
    <inertial>
      <origin rpy="0 0 0" xyz="0 0 0"/>
      <mass value="0.001"/>
      <inertia ixx="0.001" ixy="0" ixz="0" iyy="0.001" iyz="0" izz="0.001"/>
    </inertial>
  </link>
  <link name="right_eye_vertical_link">
    <inertial>
      <origin rpy="0 0 0" xyz="0 0 0"/>
      <mass value="0.001"/>
      <inertia ixx="0.001" ixy="0" ixz="0" iyy="0.001" iyz="0" izz="0.001"/>
    </inertial>
    <visual name="right_eye">
      <origin rpy="-1.5708 0 0" xyz="0 0 0"/>
      <geometry>
        <mesh filename="package://boris_head_description/meshes/dae/Cube.007.dae" scale="0.001 0.001 0.001"/>
      </geometry>
      <material name="WHITE_004"/>
    </visual>
  </link>
  <link name="right_inferior_eyelid_link">
    <inertial>
      <origin rpy="0 0 0" xyz="0 0 0"/>
      <mass value="0.001"/>
      <inertia ixx="0.001" ixy="0" ixz="0" iyy="0.001" iyz="0" izz="0.001"/>
    </inertial>
    <visual name="right_inferior_eyelid">
      <origin rpy="-1.5708 0 0" xyz="0.0038 -0.01141 -0.01966"/>
      <geometry>
        <mesh filename="package://boris_head_description/meshes/dae/Plane.013.dae" scale="0.001 0.001 0.001"/>
      </geometry>
      <material name="Gray_001"/>
    </visual>
  </link>
  <link name="right_superior_eyelid_link">
    <inertial>
      <origin rpy="0 0 0" xyz="0 0 0"/>
      <mass value="0.001"/>
      <inertia ixx="0.001" ixy="0" ixz="0" iyy="0.001" iyz="0" izz="0.001"/>
    </inertial>
    <visual name="right_superior_eyelid">
      <origin rpy="1.5708 0 0.3358" xyz="0.00701 -0.01106 -0.01469"/>
      <geometry>
        <mesh filename="package://boris_head_description/meshes/dae/Plane.014.dae" scale="0.001 0.001 0.001"/>
      </geometry>
      <material name="Gray_001"/>
    </visual>
  </link>
  <link name="head_root">
    <inertial>
      <origin rpy="0 0 0" xyz="0 0 0"/>
      <mass value="0.001"/>
      <inertia ixx="0.001" ixy="0" ixz="0" iyy="0.001" iyz="0" izz="0.001"/>
    </inertial>
  </link>
  <joint name="horizontal_neck_joint" type="revolute">
    <origin rpy="0 0 1.5708" xyz="0 0 0"/>
    <parent link="head_root"/>
    <child link="neck_link"/>
    <axis xyz="0 0 1.0"/>
    <limit effort="1.0" lower="-0.86" upper="0.86" velocity="10"/>
  </joint>
  <joint name="jaw_joint" type="revolute">
    <origin rpy="0 0 0" xyz="0.00668 -0.10888 0.05845"/>
    <parent link="head_link"/>
    <child link="jaw_link"/>
    <axis xyz="0 0 1.0"/>
    <limit effort="1.0" lower="0" upper="0.5" velocity="10"/>
  </joint>
  <joint name="left_eye_horizontal_joint" type="revolute">
    <origin rpy="1.5708 0 0" xyz="0.09352 -0.08739 -0.05892"/>
    <parent link="head_link"/>
    <child link="left_eye_horizontal_link"/>
    <axis xyz="0 0 1.0"/>
    <limit effort="1.0" lower="-0.27453" upper="0.7854" velocity="10"/>
  </joint>
  <joint name="left_eye_vertical_joint" type="revolute">
    <origin rpy="1.5708 0 0" xyz="0 0 0"/>
    <parent link="left_eye_horizontal_link"/>
    <child link="left_eye_vertical_link"/>
    <axis xyz="0 0 1.0"/>
    <limit effort="1.0" lower="-0.17453" upper="0.7854" velocity="10"/>
  </joint>
  <joint name="left_inferior_eyelid_joint" type="revolute">
    <origin rpy="-3.14159 -0.06113 0" xyz="0.09208 -0.08718 -0.0824"/>
    <parent link="head_link"/>
    <child link="left_inferior_eyelid_link"/>
    <axis xyz="0 0 1.0"/>
    <limit effort="1.0" lower="-0.17453" upper="0.7854" velocity="10"/>
  </joint>
  <joint name="left_rotacional_eyebrow_joint" type="revolute">
    <origin rpy="2e-05 1.57091 6e-05" xyz="0 0 0"/>
    <parent link="left_vertical_eyebrow_link"/>
    <child link="left_rotacional_eyebrow_link"/>
    <axis xyz="0 0 1.0"/>
    <limit effort="1.0" lower="-0.17453" upper="0.4" velocity="10"/>
  </joint>
  <joint name="left_superior_eyelid_joint" type="revolute">
    <origin rpy="0 0.06113 0" xyz="0.09123 -0.0871 -0.04284"/>
    <parent link="head_link"/>
    <child link="left_superior_eyelid_link"/>
    <axis xyz="0 0 1.0"/>
    <limit effort="1.0" lower="-0.17453" upper="0.4" velocity="10"/>
  </joint>
  <joint name="left_vertical_eyebrow_joint" type="prismatic">
    <origin rpy="1.5708 0 -0.00012" xyz="0.1119 -0.12427 -0.0587"/>
    <parent link="head_link"/>
    <child link="left_vertical_eyebrow_link"/>
    <axis xyz="0 0 1.0"/>
    <limit effort="1.0" lower="0" upper="0.02" velocity="10"/>
  </joint>
  <joint name="right_rotacional_eyebrow_joint" type="revolute">
    <origin rpy="0 1.5708 0" xyz="0 0 0"/>
    <parent link="right_vertical_eyebrow_link"/>
    <child link="right_rotacional_eyebrow_link"/>
    <axis xyz="0 0 1.0"/>
    <limit effort="1.0" lower="-0.4" upper="0.17453" velocity="10"/>
  </joint>
  <joint name="right_vertical_eyebrow_joint" type="prismatic">
    <origin rpy="1.5708 0 0" xyz="0.1119 -0.12289 0.01565"/>
    <parent link="head_link"/>
    <child link="right_vertical_eyebrow_link"/>
    <axis xyz="0 0 1.0"/>
    <limit effort="1.0" lower="0" upper="0.02" velocity="10"/>
  </joint>
  <joint name="right_eye_horizontal_joint" type="revolute">
    <origin rpy="1.5708 0 0" xyz="0.09352 -0.08739 0.01605"/>
    <parent link="head_link"/>
    <child link="right_eye_horizontal_link"/>
    <axis xyz="0 0 1.0"/>
    <limit effort="1.0" lower="-0.27453" upper="0.4" velocity="10"/>
  </joint>
  <joint name="right_eye_vertical_joint" type="revolute">
    <origin rpy="1.5708 0 0" xyz="0 0 0"/>
    <parent link="right_eye_horizontal_link"/>
    <child link="right_eye_vertical_link"/>
    <axis xyz="0 0 1.0"/>
    <limit effort="1.0" lower="-0.2" upper="0.7854" velocity="10"/>
  </joint>
  <joint name="right_inferior_eyelid_joint" type="revolute">
    <origin rpy="-3.14159 0 0" xyz="0.09188 -0.08649 -0.00398"/>
    <parent link="head_link"/>
    <child link="right_inferior_eyelid_link"/>
    <axis xyz="0 0 1.0"/>
    <limit effort="1.0" lower="-0.17" upper="0.7854" velocity="10"/>
  </joint>
  <joint name="right_superior_eyelid_joint" type="revolute">
    <origin rpy="0 0 0" xyz="0.09073 -0.08626 0.03037"/>
    <parent link="head_link"/>
    <child link="right_superior_eyelid_link"/>
    <axis xyz="0 0 1.0"/>
    <limit effort="1.0" lower="-0.4" upper="0.17" velocity="10"/>
  </joint>
  <joint name="vertical_neck_joint" type="revolute">
    <origin rpy="-1.5708 0 -1.5708" xyz="0.02367 -0.00121 0.01929"/>
    <parent link="neck_link"/>
    <child link="head_link"/>
    <axis xyz="0 0 1.0"/>
    <limit effort="1.0" lower="0" upper="0.5" velocity="10"/>
  </joint>
  <transmission name="tran1">
    <type>transmission_interface/SimpleTransmission</type>
    <joint name="horizontal_neck_joint">
      <hardwareInterface>hardware_interface/EffortJointInterface</hardwareInterface>
    </joint>
    <actuator name="motor1">
      <hardwareInterface>hardware_interface/EffortJointInterface</hardwareInterface>
      <mechanicalReduction>1</mechanicalReduction>
    </actuator>
  </transmission>
  <transmission name="tran2">
    <type>transmission_interface/SimpleTransmission</type>
    <joint name="vertical_neck_joint">
      <hardwareInterface>hardware_interface/EffortJointInterface</hardwareInterface>
    </joint>
    <actuator name="motor2">
      <hardwareInterface>hardware_interface/EffortJointInterface</hardwareInterface>
      <mechanicalReduction>1</mechanicalReduction>
    </actuator>
  </transmission>
  <transmission name="tran3">
    <type>transmission_interface/SimpleTransmission</type>
    <joint name="jaw_joint">
      <hardwareInterface>hardware_interface/EffortJointInterface</hardwareInterface>
    </joint>
    <actuator name="motor3">
      <hardwareInterface>hardware_interface/EffortJointInterface</hardwareInterface>
      <mechanicalReduction>1</mechanicalReduction>
    </actuator>
  </transmission>
  <transmission name="tran4">
    <type>transmission_interface/SimpleTransmission</type>
    <joint name="right_vertical_eyebrow_joint">
      <hardwareInterface>hardware_interface/EffortJointInterface</hardwareInterface>
    </joint>
    <actuator name="motor4">
      <hardwareInterface>hardware_interface/EffortJointInterface</hardwareInterface>
      <mechanicalReduction>1</mechanicalReduction>
    </actuator>
  </transmission>
  <transmission name="tran5">
    <type>transmission_interface/SimpleTransmission</type>
    <joint name="left_vertical_eyebrow_joint">
      <hardwareInterface>hardware_interface/EffortJointInterface</hardwareInterface>
    </joint>
    <actuator name="motor5">
      <hardwareInterface>hardware_interface/EffortJointInterface</hardwareInterface>
      <mechanicalReduction>1</mechanicalReduction>
    </actuator>
  </transmission>
  <transmission name="tran6">
    <type>transmission_interface/SimpleTransmission</type>
    <joint name="right_rotacional_eyebrow_joint">
      <hardwareInterface>hardware_interface/EffortJointInterface</hardwareInterface>
    </joint>
    <actuator name="motor6">
      <hardwareInterface>hardware_interface/EffortJointInterface</hardwareInterface>
      <mechanicalReduction>1</mechanicalReduction>
    </actuator>
  </transmission>
  <transmission name="tran7">
    <type>transmission_interface/SimpleTransmission</type>
    <joint name="left_rotacional_eyebrow_joint">
      <hardwareInterface>hardware_interface/EffortJointInterface</hardwareInterface>
    </joint>
    <actuator name="motor7">
      <hardwareInterface>hardware_interface/EffortJointInterface</hardwareInterface>
      <mechanicalReduction>1</mechanicalReduction>
    </actuator>
  </transmission>
  <transmission name="tran8">
    <type>transmission_interface/SimpleTransmission</type>
    <joint name="right_superior_eyelid_joint">
      <hardwareInterface>hardware_interface/EffortJointInterface</hardwareInterface>
    </joint>
    <actuator name="motor8">
      <hardwareInterface>hardware_interface/EffortJointInterface</hardwareInterface>
      <mechanicalReduction>1</mechanicalReduction>
    </actuator>
  </transmission>
  <transmission name="tran9">
    <type>transmission_interface/SimpleTransmission</type>
    <joint name="left_superior_eyelid_joint">
      <hardwareInterface>hardware_interface/EffortJointInterface</hardwareInterface>
    </joint>
    <actuator name="motor9">
      <hardwareInterface>hardware_interface/EffortJointInterface</hardwareInterface>
      <mechanicalReduction>1</mechanicalReduction>
    </actuator>
  </transmission>
  <transmission name="tran10">
    <type>transmission_interface/SimpleTransmission</type>
    <joint name="right_inferior_eyelid_joint">
      <hardwareInterface>hardware_interface/EffortJointInterface</hardwareInterface>
    </joint>
    <actuator name="motor10">
      <hardwareInterface>hardware_interface/EffortJointInterface</hardwareInterface>
      <mechanicalReduction>1</mechanicalReduction>
    </actuator>
  </transmission>
  <transmission name="tran11">
    <type>transmission_interface/SimpleTransmission</type>
    <joint name="left_inferior_eyelid_joint">
      <hardwareInterface>hardware_interface/EffortJointInterface</hardwareInterface>
    </joint>
    <actuator name="motor11">
      <hardwareInterface>hardware_interface/EffortJointInterface</hardwareInterface>
      <mechanicalReduction>1</mechanicalReduction>
    </actuator>
  </transmission>
  <transmission name="tran12">
    <type>transmission_interface/SimpleTransmission</type>
    <joint name="right_eye_horizontal_joint">
      <hardwareInterface>hardware_interface/EffortJointInterface</hardwareInterface>
    </joint>
    <actuator name="motor12">
      <hardwareInterface>hardware_interface/EffortJointInterface</hardwareInterface>
      <mechanicalReduction>1</mechanicalReduction>
    </actuator>
  </transmission>
  <transmission name="tran13">
    <type>transmission_interface/SimpleTransmission</type>
    <joint name="left_eye_horizontal_joint">
      <hardwareInterface>hardware_interface/EffortJointInterface</hardwareInterface>
    </joint>
    <actuator name="motor13">
      <hardwareInterface>hardware_interface/EffortJointInterface</hardwareInterface>
      <mechanicalReduction>1</mechanicalReduction>
    </actuator>
  </transmission>
  <transmission name="tran14">
    <type>transmission_interface/SimpleTransmission</type>
    <joint name="right_eye_vertical_joint">
      <hardwareInterface>hardware_interface/EffortJointInterface</hardwareInterface>
    </joint>
    <actuator name="motor14">
      <hardwareInterface>hardware_interface/EffortJointInterface</hardwareInterface>
      <mechanicalReduction>1</mechanicalReduction>
    </actuator>
  </transmission>
  <transmission name="tran15">
    <type>transmission_interface/SimpleTransmission</type>
    <joint name="left_eye_vertical_joint">
      <hardwareInterface>hardware_interface/EffortJointInterface</hardwareInterface>
    </joint>
    <actuator name="motor15">
      <hardwareInterface>hardware_interface/EffortJointInterface</hardwareInterface>
      <mechanicalReduction>1</mechanicalReduction>
    </actuator>
  </transmission>
  <material name="BLACK_006">
    <color rgba="0.00291 0.00291 0.00291 1.0"/>
  </material>
  <material name="BLACK_007">
    <color rgba="0.00291 0.00291 0.00291 1.0"/>
  </material>
  <material name="Face_000">
    <color rgba="0.10651 0.09584 0.11784 1.0"/>
  </material>
  <material name="Gray_001">
    <color rgba="0.24256 0.24256 0.24256 1.0"/>
  </material>
  <material name="WHITE_003">
    <color rgba="0.64 0.64 0.64 1.0"/>
  </material>
  <material name="WHITE_004">
    <color rgba="0.64 0.64 0.64 1.0"/>
  </material>
  <ros2_control name="head_hardware_interface" type="system">
    <hardware>
      <plugin>gazebo_ros2_control/GazeboSystem</plugin>
    </hardware>
    <joint name="horizontal_neck_joint">
      <command_interface name="position">
      </command_interface>
      <state_interface name="position"/>
    </joint>
    <joint name="vertical_neck_joint">
      <command_interface name="position">
      </command_interface>
      <state_interface name="position"/>
    </joint>
  </ros2_control>
  <link name="sick_link">
    <inertial>
      <mass value="1e-5"/>
      <origin xyz="0 0 0"/>
      <inertia ixx="1e-6" ixy="1e-20" ixz="1e-20" iyy="1e-6" iyz="1e-20" izz="1e-6"/>
    </inertial>
    <visual>
      <origin rpy="0 0 0" xyz="0 0 0"/>
      <geometry>
        <mesh filename="package://sensors_description/meshes/sick-lms1xx.dae"/>
      </geometry>
    </visual>
  </link>
  <gazebo reference="sick_link">
    <sensor name="sick_link" type="gpu_ray">
      <pose>0 0 0 0 0 0</pose>
      <visualize>true</visualize>
      <update_rate>50</update_rate>
      <ray>
        <scan>
          <horizontal>
            <samples>720</samples>
            <resolution>1</resolution>
            <min_angle>-1.57</min_angle>
            <max_angle>1.57</max_angle>
          </horizontal>
        </scan>
        <range>
          <min>0.1</min>
          <max>30.0</max>
          <resolution>0.01</resolution>
        </range>
        <noise>
          <type>gaussian</type>
          <mean>0.0</mean>
          <stddev>0.001</stddev>
        </noise>
      </ray>
      <plugin filename="libgazebo_ros_ray_sensor.so" name="gazebo_ros_laser">
        <ros>
          <namespace>/lms1xx</namespace>
          <remapping>~/out:=scan</remapping>
        </ros>
        <output_type>sensor_msgs/LaserScan</output_type>
        <frame_name>sick_link</frame_name>
      </plugin>
    </sensor>
  </gazebo>
  <joint name="laser_joint" type="fixed">
    <origin rpy="0 0 0" xyz="0.317 0 0.1355"/>
    <parent link="base_link"/>
    <child link="sick_link"/>
  </joint>
  <joint name="dorso_head" type="fixed">
    <parent link="dorso_link"/>
    <child link="head_root"/>
    <origin rpy="0 0 0" xyz="0 0 0.805"/>
  </joint>
  <link name="camera_turret_pan_link">
    <inertial>
      <origin rpy="0 0 0" xyz="-1.35308431126191E-16 -2.97071395261028E-17 0.0220876265081744"/>
      <mass value="0.0182769203076134"/>
      <inertia ixx="1.32243845065555E-05" ixy="5.07660179129181E-13" ixz="1.067515220067E-20" iyy="7.13386116649085E-06" iyz="-1.32882457845217E-20" izz="7.83291781352837E-06"/>
    </inertial>
    <visual>
      <origin rpy="0 0 0" xyz="0 0 0"/>
      <geometry>
        <mesh filename="package://sensors_description/meshes/tilt_link.STL"/>
      </geometry>
      <material name="">
        <color rgba="0.250980392156863 0.250980392156863 0.250980392156863 1"/>
      </material>
    </visual>
    <collision>
      <origin rpy="0 0 0" xyz="0 0 0"/>
      <geometry>
        <mesh filename="package://sensors_description/meshes/tilt_link.STL"/>
      </geometry>
    </collision>
  </link>
  <joint name="camera_turret_pan_joint" type="revolute">
    <origin rpy="0 0 0.3925" xyz="0.191 0 0.8180000000000001"/>
    <parent link="dorso_link"/>
    <child link="camera_turret_pan_link"/>
    <axis xyz="0 0 1"/>
    <dynamics damping="100.0" friction="100.0"/>
    <limit effort="1" lower="-1.57" upper="1.57" velocity="1"/>
  </joint>
  <link name="camera_turret_tilt_link">
    <inertial>
      <origin rpy="0 0 0" xyz="0.0168744200088311 -0.000442984145897884 -0.00405256422002387"/>
      <mass value="0.0547677687275323"/>
      <inertia ixx="1.07071738005716E-05" ixy="-1.46854788384565E-07" ixz="5.59529059364376E-08" iyy="1.77011620295824E-05" iyz="1.27587154712834E-09" izz="2.01583693170578E-05"/>
    </inertial>
    <visual>
      <origin rpy="0 0 0" xyz="0 0 0"/>
      <geometry>
        <mesh filename="package://sensors_description/meshes/roll_link.STL"/>
      </geometry>
      <material name="">
        <color rgba="0.792156862745098 0.819607843137255 0.933333333333333 1"/>
      </material>
    </visual>
    <collision>
      <origin rpy="0 0 0" xyz="0 0 0"/>
      <geometry>
        <mesh filename="package://sensors_description/meshes/roll_link.STL"/>
      </geometry>
    </collision>
  </link>
  <joint name="camera_turret_tilt_joint" type="revolute">
    <origin rpy="0 0 0" xyz="0 0 0.05"/>
    <parent link="camera_turret_pan_link"/>
    <child link="camera_turret_tilt_link"/>
    <axis xyz="0 1 0"/>
    <dynamics damping="100.0" friction="100.0"/>
    <limit effort="1" lower="-1.57" upper="1.57" velocity="1"/>
  </joint>
  <ros2_control name="head_hardware_interface" type="system">
    <hardware>
      <plugin>gazebo_ros2_control/GazeboSystem</plugin>
    </hardware>
    <joint name="camera_turret_pan_joint">
      <command_interface name="position">
            </command_interface>
      <state_interface name="position"/>
    </joint>
    <joint name="camera_turret_tilt_joint">
      <command_interface name="position">
            </command_interface>
      <state_interface name="position"/>
    </joint>
  </ros2_control>
  <joint name="astra2_top_camera_base_joint" type="fixed">
    <child link="astra2_top_camera_base_link"/>
    <parent link="camera_turret_tilt_link"/>
    <origin rpy="0 0 -0.5235987755982988" xyz="0.06705 0 -0.00425"/>
  </joint>
  <!-- Camera base -->
  <link name="astra2_top_camera_base_link">
    <visual>
      <origin rpy="0 0 3.141592653589793" xyz="0 0 0"/>
      <geometry>
        <mesh filename="package://hector_models/meshes/orbbec_astra2/orbbec_astra2.dae"/>
      </geometry>
    </visual>
    <collision>
      <origin rpy="0 0 0" xyz="0.018 0 0"/>
      <geometry>
        <box size="0.037 0.147 0.035"/>
      </geometry>
    </collision>
  </link>
  <!-- Camera RGB sensor - Frame for gazebo (in x direction) -->
  <link name="astra2_top_camera_link"/>
  <joint name="astra2_top_camera_sensor_joint" type="fixed">
    <origin rpy="0 0 0" xyz="0.033 0.022 0"/>
    <parent link="astra2_top_camera_base_link"/>
    <child link="astra2_top_camera_link"/>
  </joint>
  <!-- Optical Frame for ros (in z direction) -->
  <link name="astra2_top_camera_optical_frame"/>
  <joint name="astra2_top_camera_sensor_joint_optical_frame" type="fixed">
    <origin rpy="-1.5707963267948966 0 -1.5707963267948966" xyz="0 0 0"/>
    <parent link="astra2_top_camera_link"/>
    <child link="astra2_top_camera_optical_frame"/>
  </joint>
  <gazebo reference="astra2_top_camera_link">
    <sensor name="astra2_top_camera" type="camera">
      <always_on>true</always_on>
      <visualize>true</visualize>
      <update_rate>15</update_rate>
      <topic>/wx200/astra2_top_camera/rgb/image_raw</topic>
      <gz_frame_id>astra2_top_camera_link</gz_frame_id>
      <camera name="astra2_top_camera_camera">
        <camera_info_topic>/wx200/astra2_top_camera/rgb/camera_info</camera_info_topic>
        <optical_frame_id>astra2_top_camera_optical_frame</optical_frame_id>
        <horizontal_fov>1.5707963267948966</horizontal_fov>
        <image>
          <format>R8G8B8</format>
          <width>720</width>
          <height>480</height>
        </image>
        <clip>
          <near>0.05</near>
          <far>10</far>
        </clip>
      </camera>
    </sensor>
    <sensor name="astra2_top_camera_depth" type="depth_camera">
      <always_on>true</always_on>
      <visualize>true</visualize>
      <update_rate>15</update_rate>
      <topic>/wx200/astra2_top_camera/depth/image_raw</topic>
      <gz_frame_id>astra2_top_camera_link</gz_frame_id>
      <camera>
        <camera_info_topic>/wx200/astra2_top_camera/depth/camera_info</camera_info_topic>
        <optical_frame_id>astra2_top_camera_optical_frame</optical_frame_id>
        <horizontal_fov>1.047</horizontal_fov>
        <image>
          <format>R_FLOAT32</format>
          <width>640</width>
          <height>480</height>
        </image>
        <depth_camera>
          <clip>
            <near>0.1</near>
            <far>10.0</far>
          </clip>
        </depth_camera>
        <noise>
          <type>gaussian</type>
          <mean>0.0</mean>
          <stddev>0.01</stddev>
        </noise>
      </camera>
    </sensor>
    <sensor name="astra2_top_camera_segmentation_camera" type="segmentation">
      <topic>/wx200/astra2_top_camera/segmentation</topic>
      <gz_frame_id>astra2_top_camera_link</gz_frame_id>
      <camera>
        <optical_frame_id>astra2_top_camera_optical_frame</optical_frame_id>
        <segmentation_type>instance</segmentation_type>
        <horizontal_fov>1.5707963267948966</horizontal_fov>
        <image>
          <width>720</width>
          <height>480</height>
        </image>
        <clip>
          <near>0.1</near>
          <far>10</far>
        </clip>
      </camera>
      <update_rate>5</update_rate>
    </sensor>
  </gazebo>
  <link name="dorso_link">
    <inertial>
      <mass value="1"/>
      <inertia ixx="0.04877708333333333" ixy="0.0" ixz="0.0" iyy="0.05828908333333333" iyz="0.0" izz="0.009528666666666668"/>
    </inertial>
    <visual>
      <origin xyz="0.0 0.0 0.3825"/>
      <material name="lightgray"/>
      <geometry>
        <box size="0.282 0.338 0.765"/>
      </geometry>
    </visual>
    <collision>
      <origin xyz="0.0 0.0 0.3825"/>
      <geometry>
        <box size="0.282 0.338 0.765"/>
      </geometry>
    </collision>
  </link>
  <joint name="dorso_joint" type="fixed">
    <parent link="base_link"/>
    <child link="dorso_link"/>
    <origin rpy="0 0 0" xyz="-0.10900000000000001 0 0.1155"/>
  </joint>
  <link name="arm_support_link">
    <inertial>
      <mass value="1"/>
      <inertia ixx="0.00019241666666666664" ixy="0.0" ixz="0.0" iyy="0.009592083333333334" iyz="0.0" izz="0.009416333333333334"/>
    </inertial>
    <visual>
      <material name="lightgray"/>
      <geometry>
        <box size="0.325 0.336 0.047"/>
      </geometry>
    </visual>
    <collision>
      <geometry>
        <box size="0.325 0.336 0.047"/>
      </geometry>
    </collision>
  </link>
  <joint name="arm_support_joint" type="fixed">
    <parent link="dorso_link"/>
    <child link="arm_support_link"/>
    <origin rpy="0 0 0" xyz="0.3035 0 0.34"/>
  </joint>
  <link name="hokuyo_ground_link">
    <visual>
      <origin rpy="0 0 0" xyz="0 0 0"/>
      <geometry>
        <mesh filename="package://sensors_description/meshes/hokuyo.dae"/>
      </geometry>
    </visual>
    <inertial>
      <mass value="1e-5"/>
      <origin rpy="0 0 0" xyz="0 0 0"/>
      <inertia ixx="1e-6" ixy="0" ixz="0" iyy="1e-6" iyz="0" izz="1e-6"/>
    </inertial>
  </link>
  <joint name="hokuyo_ground_joint" type="fixed">
    <origin rpy="3.14 0 0" xyz="0.29100000000000004 0 -0.0955"/>
    <parent link="base_link"/>
    <child link="hokuyo_ground_link"/>
  </joint>
  <gazebo reference="hokuyo_ground_link">
    <sensor name="ground_hokuyo_sensor" type="gpu_ray">
      <pose>0 0 0 0 0 0</pose>
      <visualize>true</visualize>
      <update_rate>40</update_rate>
      <ray>
        <scan>
          <horizontal>
            <samples>683</samples>
            <resolution>0.3515625</resolution>
            <min_angle>-2.0943</min_angle>
            <max_angle>2.0943</max_angle>
          </horizontal>
        </scan>
        <range>
          <min>0.15</min>
          <max>4.0</max>
          <resolution>0.01</resolution>
        </range>
        <noise>
          <type>gaussian</type>
          <mean>0.0</mean>
          <stddev>0.01</stddev>
        </noise>
      </ray>
      <plugin filename="libgazebo_ros_ray_sensor.so" name="gazebo_ros_ground_hokuyo_controller">
        <ros>
          <remapping>~/out:=/ground/scan</remapping>
          <namespace>/ground</namespace>
        </ros>
        <frame_name>hokuyo_ground_link</frame_name>
        <output_type>sensor_msgs/LaserScan</output_type>
      </plugin>
    </sensor>
  </gazebo>
  <link name="hokuyo_back_link">
    <visual>
      <origin rpy="0 0 0" xyz="0 0 0"/>
      <geometry>
        <mesh filename="package://sensors_description/meshes/hokuyo.dae"/>
      </geometry>
    </visual>
    <inertial>
      <mass value="1e-5"/>
      <origin rpy="0 0 0" xyz="0 0 0"/>
      <inertia ixx="1e-6" ixy="0" ixz="0" iyy="1e-6" iyz="0" izz="1e-6"/>
    </inertial>
  </link>
  <joint name="hokuyo_back_joint" type="fixed">
    <origin rpy="3.14 0 3.14" xyz="-0.29100000000000004 0 -0.0955"/>
    <parent link="base_link"/>
    <child link="hokuyo_back_link"/>
  </joint>
  <gazebo reference="hokuyo_back_link">
    <sensor name="back_hokuyo_sensor" type="gpu_ray">
      <pose>0 0 0 0 0 0</pose>
      <visualize>true</visualize>
      <update_rate>40</update_rate>
      <ray>
        <scan>
          <horizontal>
            <samples>683</samples>
            <resolution>0.3515625</resolution>
            <min_angle>-2.0943</min_angle>
            <max_angle>2.0943</max_angle>
          </horizontal>
        </scan>
        <range>
          <min>0.15</min>
          <max>4.0</max>
          <resolution>0.01</resolution>
        </range>
        <noise>
          <type>gaussian</type>
          <mean>0.0</mean>
          <stddev>0.01</stddev>
        </noise>
      </ray>
      <plugin filename="libgazebo_ros_ray_sensor.so" name="gazebo_ros_back_hokuyo_controller">
        <ros>
          <remapping>~/out:=/back/scan</remapping>
          <namespace>/back</namespace>
        </ros>
        <frame_name>hokuyo_back_link</frame_name>
        <output_type>sensor_msgs/LaserScan</output_type>
      </plugin>
    </sensor>
  </gazebo>
  <link name="imu_link"/>
  <joint name="imu_joint" type="fixed">
    <parent link="base_link"/>
    <child link="imu_link"/>
    <origin rpy="-0.014161 -0.0203861 0" xyz="-0.01 0 -0.0955"/>
  </joint>
  <gazebo reference="dorso_link">
    <material>Gazebo/DarkGray</material>
  </gazebo>
  <gazebo reference="arm_support_link">
    <material>Gazebo/DarkGray</material>
  </gazebo>
  <joint name="arm_support_arm_base" type="fixed">
    <parent link="arm_support_link"/>
    <child link="wx200/base_link"/>
    <origin rpy="0 0 0" xyz="0.1 0 0.0235"/>
  </joint>
  <joint name="astra2_wrist_camera_base_joint" type="fixed">
    <child link="astra2_wrist_camera_base_link"/>
    <parent link="wx200/gripper_bar_link"/>
    <origin rpy="0 0 0" xyz="-0.078 0.0 0.05"/>
  </joint>
  <!-- Camera base -->
  <link name="astra2_wrist_camera_base_link">
    <visual>
      <origin rpy="0 0 3.141592653589793" xyz="0 0 0"/>
      <geometry>
        <mesh filename="package://hector_models/meshes/orbbec_astra2/orbbec_astra2.dae"/>
      </geometry>
    </visual>
    <collision>
      <origin rpy="0 0 0" xyz="0.018 0 0"/>
      <geometry>
        <box size="0.037 0.147 0.035"/>
      </geometry>
    </collision>
  </link>
  <!-- Camera RGB sensor - Frame for gazebo (in x direction) -->
  <link name="astra2_wrist_camera_link"/>
  <joint name="astra2_wrist_camera_sensor_joint" type="fixed">
    <origin rpy="0 0 0" xyz="0.033 0.022 0"/>
    <parent link="astra2_wrist_camera_base_link"/>
    <child link="astra2_wrist_camera_link"/>
  </joint>
  <!-- Optical Frame for ros (in z direction) -->
  <link name="astra2_wrist_camera_optical_frame"/>
  <joint name="astra2_wrist_camera_sensor_joint_optical_frame" type="fixed">
    <origin rpy="-1.5707963267948966 0 -1.5707963267948966" xyz="0 0 0"/>
    <parent link="astra2_wrist_camera_link"/>
    <child link="astra2_wrist_camera_optical_frame"/>
  </joint>
  <gazebo reference="astra2_wrist_camera_link">
    <sensor name="astra2_wrist_camera" type="camera">
      <always_on>true</always_on>
      <visualize>true</visualize>
      <update_rate>15</update_rate>
      <topic>/wx200/astra2_wrist_camera/rgb/image_raw</topic>
      <gz_frame_id>astra2_wrist_camera_link</gz_frame_id>
      <camera name="astra2_wrist_camera_camera">
        <camera_info_topic>/wx200/astra2_wrist_camera/rgb/camera_info</camera_info_topic>
        <optical_frame_id>astra2_wrist_camera_optical_frame</optical_frame_id>
        <horizontal_fov>1.5707963267948966</horizontal_fov>
        <image>
          <format>R8G8B8</format>
          <width>720</width>
          <height>480</height>
        </image>
        <clip>
          <near>0.05</near>
          <far>10</far>
        </clip>
      </camera>
    </sensor>
    <sensor name="astra2_wrist_camera_depth" type="depth_camera">
      <always_on>true</always_on>
      <visualize>true</visualize>
      <update_rate>15</update_rate>
      <topic>/wx200/astra2_wrist_camera/depth/image_raw</topic>
      <gz_frame_id>astra2_wrist_camera_link</gz_frame_id>
      <camera>
        <camera_info_topic>/wx200/astra2_wrist_camera/depth/camera_info</camera_info_topic>
        <optical_frame_id>astra2_wrist_camera_optical_frame</optical_frame_id>
        <horizontal_fov>1.047</horizontal_fov>
        <image>
          <format>R_FLOAT32</format>
          <width>640</width>
          <height>480</height>
        </image>
        <depth_camera>
          <clip>
            <near>0.1</near>
            <far>10.0</far>
          </clip>
        </depth_camera>
        <noise>
          <type>gaussian</type>
          <mean>0.0</mean>
          <stddev>0.01</stddev>
        </noise>
      </camera>
    </sensor>
    <sensor name="astra2_wrist_camera_segmentation_camera" type="segmentation">
      <topic>/wx200/astra2_wrist_camera/segmentation</topic>
      <gz_frame_id>astra2_wrist_camera_link</gz_frame_id>
      <camera>
        <optical_frame_id>astra2_wrist_camera_optical_frame</optical_frame_id>
        <segmentation_type>instance</segmentation_type>
        <horizontal_fov>1.5707963267948966</horizontal_fov>
        <image>
          <width>720</width>
          <height>480</height>
        </image>
        <clip>
          <near>0.1</near>
          <far>10</far>
        </clip>
      </camera>
      <update_rate>5</update_rate>
    </sensor>
  </gazebo>
  <material name="interbotix_black">
    <texture filename="package://interbotix_xsarm_descriptions/meshes/interbotix_black.png"/>
  </material>
  <!-- use_world_frame -->
  <link name="wx200/base_link">
    <visual>
      <origin rpy="0 0 1.5707963267948966" xyz="0 0 0"/>
      <geometry>
        <mesh filename="package://interbotix_xsarm_descriptions/meshes/wx200_meshes/base.stl" scale="0.001 0.001 0.001"/>
      </geometry>
      <material name="interbotix_black"/>
    </visual>
    <collision>
      <origin rpy="0 0 1.5707963267948966" xyz="0 0 0"/>
      <geometry>
        <mesh filename="package://interbotix_xsarm_descriptions/meshes/wx200_meshes/base.stl" scale="0.001 0.001 0.001"/>
      </geometry>
    </collision>
    <inertial>
      <origin rpy="0 0 1.5707963267948966" xyz="-0.0381747000 0.0006478630 0.0193458000"/>
      <mass value="0.540142"/>
      <inertia ixx="0.0021190000" ixy="-0.0000172100" ixz="0.0000006389" iyy="0.0006925000" iyz="0.0000461200" izz="0.0025280000"/>
    </inertial>
  </link>
  <joint name="waist" type="revolute">
    <axis xyz="0 0 1"/>
    <limit effort="8" lower="-3.141582653589793" upper="3.141582653589793" velocity="3.141592653589793"/>
    <origin rpy="0 0 0" xyz="0 0 0.072"/>
    <parent link="wx200/base_link"/>
    <child link="wx200/shoulder_link"/>
    <dynamics damping="0.1" friction="0.1"/>
  </joint>
  <link name="wx200/shoulder_link">
    <visual>
      <origin rpy="0 0 1.5707963267948966" xyz="0 0 -0.003"/>
      <geometry>
        <mesh filename="package://interbotix_xsarm_descriptions/meshes/wx200_meshes/shoulder.stl" scale="0.001 0.001 0.001"/>
      </geometry>
      <material name="interbotix_black"/>
    </visual>
    <collision>
      <origin rpy="0 0 1.5707963267948966" xyz="0 0 -0.003"/>
      <geometry>
        <mesh filename="package://interbotix_xsarm_descriptions/meshes/wx200_meshes/shoulder.stl" scale="0.001 0.001 0.001"/>
      </geometry>
    </collision>
    <inertial>
      <origin rpy="0 0 1.5707963267948966" xyz="0.0000223210 0.0000414608 0.0066287000"/>
      <mass value="0.480879"/>
      <inertia ixx="0.0003790000" ixy="0.0000000022" ixz="-0.0000003561" iyy="0.0005557000" iyz="0.0000012247" izz="0.0005889000"/>
    </inertial>
  </link>
  <joint name="shoulder" type="revolute">
    <axis xyz="0 1 0"/>
    <limit effort="18" lower="-1.8849555921538759" upper="1.9722220547535925" velocity="1"/>
    <origin rpy="0 0 0" xyz="0 0 0.03865"/>
    <parent link="wx200/shoulder_link"/>
    <child link="wx200/upper_arm_link"/>
    <dynamics damping="0.1" friction="0.1"/>
  </joint>
  <link name="wx200/upper_arm_link">
    <visual>
      <origin rpy="0 0 1.5707963267948966" xyz="0 0 0"/>
      <geometry>
        <mesh filename="package://interbotix_xsarm_descriptions/meshes/wx200_meshes/upper_arm.stl" scale="0.001 0.001 0.001"/>
      </geometry>
      <material name="interbotix_black"/>
    </visual>
    <collision>
      <origin rpy="0 0 1.5707963267948966" xyz="0 0 0"/>
      <geometry>
        <mesh filename="package://interbotix_xsarm_descriptions/meshes/wx200_meshes/upper_arm.stl" scale="0.001 0.001 0.001"/>
      </geometry>
    </collision>
    <inertial>
      <origin rpy="0 0 1.5707963267948966" xyz="0.0119707000 -0.0001179264 0.1394290000"/>
      <mass value="0.297781"/>
      <inertia ixx="0.0017100000" ixy="-0.0000011433" ixz="0.0000021161" iyy="0.0016310000" iyz="0.0002135000" izz="0.0001482000"/>
    </inertial>
  </link>
  <joint name="elbow" type="revolute">
    <axis xyz="0 1 0"/>
    <limit effort="13" lower="-1.8849555921538759" upper="1.6231562043547265" velocity="3.141592653589793"/>
    <origin rpy="0 0 0" xyz="0.05 0 0.2"/>
    <parent link="wx200/upper_arm_link"/>
    <child link="wx200/forearm_link"/>
    <dynamics damping="0.1" friction="0.1"/>
  </joint>
  <link name="wx200/forearm_link">
    <visual>
      <origin rpy="0 0 1.5707963267948966" xyz="0 0 0"/>
      <geometry>
        <mesh filename="package://interbotix_xsarm_descriptions/meshes/wx200_meshes/forearm.stl" scale="0.001 0.001 0.001"/>
      </geometry>
      <material name="interbotix_black"/>
    </visual>
    <collision>
      <origin rpy="0 0 1.5707963267948966" xyz="0 0 0"/>
      <geometry>
        <mesh filename="package://interbotix_xsarm_descriptions/meshes/wx200_meshes/forearm.stl" scale="0.001 0.001 0.001"/>
      </geometry>
    </collision>
    <inertial>
      <origin rpy="0 0 1.5707963267948966" xyz="0.1211920000 -0.0001238123 0.0000000000"/>
      <mass value="0.283651"/>
      <inertia ixx="0.0011850000" ixy="-0.0000024317" ixz="0.0000000000" iyy="0.0000682900" iyz="0.0000000000" izz="0.0012060000"/>
    </inertial>
  </link>
  <joint name="wrist_angle" type="revolute">
    <axis xyz="0 1 0"/>
    <limit effort="5" lower="-1.7453292519943295" upper="2.1467549799530254" velocity="3.141592653589793"/>
    <origin rpy="0 0 0" xyz="0.2 0 0"/>
    <parent link="wx200/forearm_link"/>
    <child link="wx200/wrist_link"/>
    <dynamics damping="0.1" friction="0.1"/>
  </joint>
  <link name="wx200/wrist_link">
    <visual>
      <origin rpy="0 0 1.5707963267948966" xyz="0 0 0"/>
      <geometry>
        <mesh filename="package://interbotix_xsarm_descriptions/meshes/wx200_meshes/wrist.stl" scale="0.001 0.001 0.001"/>
      </geometry>
      <material name="interbotix_black"/>
    </visual>
    <collision>
      <origin rpy="0 0 1.5707963267948966" xyz="0 0 0"/>
      <geometry>
        <mesh filename="package://interbotix_xsarm_descriptions/meshes/wx200_meshes/wrist.stl" scale="0.001 0.001 0.001"/>
      </geometry>
    </collision>
    <inertial>
      <origin rpy="0 0 1.5707963267948966" xyz="0.0423600000 -0.0000106630 0.0105770000"/>
      <mass value="0.084957"/>
      <inertia ixx="0.0000308200" ixy="0.0000000191" ixz="0.0000000023" iyy="0.0000282200" iyz="0.0000025481" izz="0.0000315200"/>
    </inertial>
  </link>
  <!-- Include the gripper if used -->
  <joint name="wrist_rotate" type="revolute">
    <axis xyz="1 0 0"/>
    <limit effort="1" lower="-3.141582653589793" upper="3.141582653589793" velocity="3.141592653589793"/>
    <origin rpy="0 0 0" xyz="0.065 0 0"/>
    <parent link="wx200/wrist_link"/>
    <child link="wx200/gripper_link"/>
    <dynamics damping="0.1" friction="0.1"/>
  </joint>
  <link name="wx200/gripper_link">
    <visual>
      <origin rpy="0 0 1.5707963267948966" xyz="-0.02 0 0"/>
      <geometry>
        <mesh filename="package://interbotix_xsarm_descriptions/meshes/wx200_meshes/gripper.stl" scale="0.001 0.001 0.001"/>
      </geometry>
      <material name="interbotix_black"/>
    </visual>
    <collision>
      <origin rpy="0 0 1.5707963267948966" xyz="-0.02 0 0"/>
      <geometry>
        <mesh filename="package://interbotix_xsarm_descriptions/meshes/wx200_meshes/gripper.stl" scale="0.001 0.001 0.001"/>
      </geometry>
    </collision>
    <inertial>
      <origin rpy="0 0 1.5707963267948966" xyz="0.0216310000 0.0000002516 0.0114100000"/>
      <mass value="0.072885"/>
      <inertia ixx="0.0000253700" ixy="0.0000000000" ixz="0.0000000000" iyy="0.0000183600" iyz="0.0000004340" izz="0.0000167400"/>
    </inertial>
  </link>
  <joint name="ee_arm" type="fixed">
    <axis xyz="1 0 0"/>
    <origin rpy="0 0 0" xyz="0.043 0 0"/>
    <parent link="wx200/gripper_link"/>
    <child link="wx200/ee_arm_link"/>
  </joint>
  <link name="wx200/ee_arm_link">
    <inertial>
      <mass value="0.001"/>
      <inertia ixx="0.001" ixy="0" ixz="0" iyy="0.001" iyz="0" izz="0.001"/>
    </inertial>
  </link>
  <joint name="gripper" type="continuous">
    <axis xyz="1 0 0"/>
    <limit effort="1" velocity="3.141592653589793"/>
    <origin rpy="0 0 0" xyz="0.0055 0 0"/>
    <parent link="wx200/ee_arm_link"/>
    <child link="wx200/gripper_prop_link"/>
    <dynamics damping="0.1" friction="0.1"/>
  </joint>
  <link name="wx200/gripper_prop_link">
    <visual>
      <origin rpy="0 0 1.5707963267948966" xyz="-0.0685 0 0"/>
      <geometry>
        <mesh filename="package://interbotix_xsarm_descriptions/meshes/wx200_meshes/gripper_prop.stl" scale="0.001 0.001 0.001"/>
      </geometry>
      <material name="interbotix_black"/>
    </visual>
    <collision>
      <origin rpy="0 0 1.5707963267948966" xyz="-0.0685 0 0"/>
      <geometry>
        <mesh filename="package://interbotix_xsarm_descriptions/meshes/wx200_meshes/gripper_prop.stl" scale="0.001 0.001 0.001"/>
      </geometry>
    </collision>
    <inertial>
      <origin rpy="0 0 1.5707963267948966" xyz="0.0008460000 -0.0000016817 0.0000420000"/>
      <mass value="0.00434"/>
      <inertia ixx="0.0000005923" ixy="0.0000000000" ixz="0.0000003195" iyy="0.0000011156" iyz="-0.0000000004" izz="0.0000005743"/>
    </inertial>
  </link>
  <!-- If the AR tag is being used, then add the AR tag mount -->
  <!-- show_ar_tag -->
  <!-- If the gripper bar is being used, then also add the gripper bar -->
  <joint name="gripper_bar" type="fixed">
    <axis xyz="1 0 0"/>
    <origin rpy="0 0 0" xyz="0 0 0"/>
    <parent link="wx200/ee_arm_link"/>
    <child link="wx200/gripper_bar_link"/>
  </joint>
  <link name="wx200/gripper_bar_link">
    <visual>
      <origin rpy="0 0 1.5707963267948966" xyz="-0.063 0 0"/>
      <geometry>
        <mesh filename="package://interbotix_xsarm_descriptions/meshes/wx200_meshes/gripper_bar.stl" scale="0.001 0.001 0.001"/>
      </geometry>
      <material name="interbotix_black"/>
    </visual>
    <collision>
      <origin rpy="0 0 1.5707963267948966" xyz="-0.063 0 0"/>
      <geometry>
        <mesh filename="package://interbotix_xsarm_descriptions/meshes/wx200_meshes/gripper_bar.stl" scale="0.001 0.001 0.001"/>
      </geometry>
    </collision>
    <inertial>
      <origin rpy="0 0 1.5707963267948966" xyz="0.0096870000 0.0000008177 0.0049620000"/>
      <mass value="0.034199"/>
      <inertia ixx="0.0000074125" ixy="-0.0000000008" ixz="-0.0000000006" iyy="0.0000284300" iyz="-0.0000013889" izz="0.0000286000"/>
    </inertial>
  </link>
  <joint name="ee_bar" type="fixed">
    <axis xyz="1 0 0"/>
    <origin rpy="0 0 0" xyz="0.023 0 0"/>
    <parent link="wx200/gripper_bar_link"/>
    <child link="wx200/fingers_link"/>
  </joint>
  <link name="wx200/fingers_link">
    <inertial>
      <mass value="0.001"/>
      <inertia ixx="0.001" ixy="0" ixz="0" iyy="0.001" iyz="0" izz="0.001"/>
    </inertial>
  </link>
  <!-- If the gripper fingers are being used, add those as well -->
  <joint name="left_finger" type="prismatic">
    <axis xyz="0 1 0"/>
    <limit effort="5" lower="0.015" upper="0.037" velocity="1"/>
    <origin rpy="0 0 0" xyz="0 0 0"/>
    <parent link="wx200/fingers_link"/>
    <child link="wx200/left_finger_link"/>
    <dynamics damping="0.1" friction="0.1"/>
  </joint>
  <link name="wx200/left_finger_link">
    <visual>
      <origin rpy="3.141592653589793 3.141592653589793 0" xyz="0 0.005 0"/>
      <geometry>
        <mesh filename="package://interbotix_xsarm_descriptions/meshes/wx200_meshes/gripper_finger.stl" scale="0.001 0.001 0.001"/>
      </geometry>
      <material name="interbotix_black"/>
    </visual>
    <collision>
      <origin rpy="3.141592653589793 3.141592653589793 0" xyz="0 0.005 0"/>
      <geometry>
        <mesh filename="package://interbotix_xsarm_descriptions/meshes/wx200_meshes/gripper_finger.stl" scale="0.001 0.001 0.001"/>
      </geometry>
    </collision>
    <inertial>
      <origin rpy="3.141592653589793 3.141592653589793 1.5707963267948966" xyz="0.0138160000 0.0000000000 0.0000000000"/>
      <mass value="0.016246"/>
      <inertia ixx="0.0000047310" ixy="-0.0000004560" ixz="0.0000000000" iyy="0.0000015506" iyz="0.0000000000" izz="0.0000037467"/>
    </inertial>
  </link>
  <joint name="right_finger" type="prismatic">
    <axis xyz="0 1 0"/>
    <limit effort="5" lower="-0.037" upper="-0.015" velocity="1"/>
    <origin rpy="0 0 0" xyz="0 0 0"/>
    <parent link="wx200/fingers_link"/>
    <child link="wx200/right_finger_link"/>
    <dynamics damping="0.1" friction="0.1"/>
    <mimic joint="left_finger" multiplier="-1" offset="0"/>
  </joint>
  <link name="wx200/right_finger_link">
    <visual>
      <origin rpy="0 3.141592653589793 0" xyz="0 -0.005 0"/>
      <geometry>
        <mesh filename="package://interbotix_xsarm_descriptions/meshes/wx200_meshes/gripper_finger.stl" scale="0.001 0.001 0.001"/>
      </geometry>
      <material name="interbotix_black"/>
    </visual>
    <collision>
      <origin rpy="0 3.141592653589793 0" xyz="0 -0.005 0"/>
      <geometry>
        <mesh filename="package://interbotix_xsarm_descriptions/meshes/wx200_meshes/gripper_finger.stl" scale="0.001 0.001 0.001"/>
      </geometry>
    </collision>
    <inertial>
      <origin rpy="0 3.141592653589793 1.5707963267948966" xyz="0.0138160000 0.0000000000  0.0000000000"/>
      <mass value="0.016246"/>
      <inertia ixx="0.0000047310" ixy="0.0000004560" ixz="0.0000000000" iyy="0.0000015506" iyz="0.0000000000" izz="0.0000037467"/>
    </inertial>
  </link>
  <joint name="ee_gripper" type="fixed">
    <axis xyz="1 0 0"/>
    <origin rpy="0 0 0" xyz="0.027575 0 0"/>
    <parent link="wx200/fingers_link"/>
    <child link="wx200/ee_gripper_link"/>
  </joint>
  <link name="wx200/ee_gripper_link">
    <inertial>
      <mass value="0.001"/>
      <inertia ixx="0.001" ixy="0" ixz="0" iyy="0.001" iyz="0" izz="0.001"/>
    </inertial>
  </link>
  <!-- show_gripper_fingers -->
  <!-- show_gripper_bar -->
  <!-- use_gripper -->
  <ros2_control name="XSHardwareInterface" type="system">
    <hardware>
      <plugin>interbotix_xs_ros_control/XSHardwareInterface</plugin>
      <param name="loop_hz">10</param>
      <param name="group_name">arm</param>
      <param name="gripper_name">gripper</param>
      <param name="joint_states_topic">joint_states</param>
    </hardware>
    <joint name="waist">
      <command_interface name="position">
        <param name="min">&quot;-3.141582653589793&quot;</param>
        <param name="max">&quot;3.141582653589793&quot;</param>
      </command_interface>
      <state_interface name="position"/>
    </joint>
    <joint name="shoulder">
      <command_interface name="position">
        <param name="min">&quot;-1.8849555921538759&quot;</param>
        <param name="max">&quot;1.9722220547535925&quot;</param>
      </command_interface>
      <state_interface name="position"/>
    </joint>
    <joint name="elbow">
      <command_interface name="position">
        <param name="min">&quot;-1.8849555921538759&quot;</param>
        <param name="max">&quot;1.6231562043547265&quot;</param>
      </command_interface>
      <state_interface name="position"/>
    </joint>
    <joint name="wrist_angle">
      <command_interface name="position">
        <param name="min">&quot;-1.7453292519943295&quot;</param>
        <param name="max">&quot;2.1467549799530254&quot;</param>
      </command_interface>
      <state_interface name="position"/>
    </joint>
    <joint name="wrist_rotate">
      <command_interface name="position">
        <param name="min">&quot;-3.141582653589793&quot;</param>
        <param name="max">&quot;3.141582653589793&quot;</param>
      </command_interface>
      <state_interface name="position"/>
    </joint>
    <joint name="left_finger">
      <command_interface name="position">
        <param name="min">&quot;0.015&quot;</param>
        <param name="max">&quot;-0.015&quot;</param>
      </command_interface>
      <state_interface name="position"/>
    </joint>
  </ros2_control>
</robot>
